Mon, 13 Feb 2017 16:06:15 exception.py[line:124] ERROR Internal Server Error: /lists/new
Traceback (most recent call last):
  File "C:\Python27\lib\site-packages\django\core\handlers\exception.py", line 39, in inner
    response = get_response(request)
  File "C:\Python27\lib\site-packages\django\core\handlers\base.py", line 187, in _get_response
    response = self.process_exception_by_middleware(e, request)
  File "C:\Python27\lib\site-packages\django\core\handlers\base.py", line 185, in _get_response
    response = wrapped_callback(request, *callback_args, **callback_kwargs)
  File "D:\Projects\Test-Driven-Development-V0.1\superlists\lists\views.py", line 29, in new_list
    print request.POST['item_text']
  File "C:\Python27\lib\site-packages\django\utils\datastructures.py", line 85, in __getitem__
    raise MultiValueDictKeyError(repr(key))
MultiValueDictKeyError: "'item_text'"
Mon, 13 Feb 2017 16:08:04 exception.py[line:124] ERROR Internal Server Error: /lists/new
Traceback (most recent call last):
  File "C:\Python27\lib\site-packages\django\core\handlers\exception.py", line 39, in inner
    response = get_response(request)
  File "C:\Python27\lib\site-packages\django\core\handlers\base.py", line 187, in _get_response
    response = self.process_exception_by_middleware(e, request)
  File "C:\Python27\lib\site-packages\django\core\handlers\base.py", line 185, in _get_response
    response = wrapped_callback(request, *callback_args, **callback_kwargs)
  File "D:\Projects\Test-Driven-Development-V0.1\superlists\lists\views.py", line 29, in new_list
    print request.POST['item_text']
  File "C:\Python27\lib\site-packages\django\utils\datastructures.py", line 85, in __getitem__
    raise MultiValueDictKeyError(repr(key))
MultiValueDictKeyError: "'item_text'"
Mon, 13 Feb 2017 16:09:03 exception.py[line:124] ERROR Internal Server Error: /lists/new
Traceback (most recent call last):
  File "C:\Python27\lib\site-packages\django\core\handlers\exception.py", line 39, in inner
    response = get_response(request)
  File "C:\Python27\lib\site-packages\django\core\handlers\base.py", line 187, in _get_response
    response = self.process_exception_by_middleware(e, request)
  File "C:\Python27\lib\site-packages\django\core\handlers\base.py", line 185, in _get_response
    response = wrapped_callback(request, *callback_args, **callback_kwargs)
  File "D:\Projects\Test-Driven-Development-V0.1\superlists\lists\views.py", line 30, in new_list
    logger.warn(55555555555555555555555)
AttributeError: 'module' object has no attribute 'warn'
Mon, 13 Feb 2017 16:10:02 exception.py[line:124] ERROR Internal Server Error: /lists/new
Traceback (most recent call last):
  File "C:\Python27\lib\site-packages\django\core\handlers\exception.py", line 39, in inner
    response = get_response(request)
  File "C:\Python27\lib\site-packages\django\core\handlers\base.py", line 187, in _get_response
    response = self.process_exception_by_middleware(e, request)
  File "C:\Python27\lib\site-packages\django\core\handlers\base.py", line 185, in _get_response
    response = wrapped_callback(request, *callback_args, **callback_kwargs)
  File "D:\Projects\Test-Driven-Development-V0.1\superlists\lists\views.py", line 30, in new_list
    logger.warnning(55555555555555555555555)
AttributeError: 'module' object has no attribute 'warnning'
Mon, 13 Feb 2017 16:10:45 views.py[line:30] WARNING 55555555555555555555555
Mon, 13 Feb 2017 16:21:19 base.py[line:152] WARNING Not Found: /favicon.ico
Mon, 13 Feb 2017 16:21:19 base.py[line:152] WARNING Not Found: /favicon.ico
Mon, 13 Feb 2017 16:21:19 remote_connection.py[line:517] DEBUG Finished Request
Mon, 13 Feb 2017 16:21:19 remote_connection.py[line:422] DEBUG POST http://127.0.0.1:57704/session/f8dcc63a-5847-478c-90e4-c6106760672c/element {"using": "css selector", "sessionId": "f8dcc63a-5847-478c-90e4-c6106760672c", "value": "[id=\"id_new_item\"]"}
Mon, 13 Feb 2017 16:21:22 remote_connection.py[line:517] DEBUG Finished Request
Mon, 13 Feb 2017 16:21:22 remote_connection.py[line:422] DEBUG DELETE http://127.0.0.1:57704/session/f8dcc63a-5847-478c-90e4-c6106760672c {"sessionId": "f8dcc63a-5847-478c-90e4-c6106760672c"}
Mon, 13 Feb 2017 16:21:22 remote_connection.py[line:517] DEBUG Finished Request
